<?xml version="1.0" ?>
<!-- =================================================================================== -->
<!-- |    This document was autogenerated by xacro from igus_rebel_robot2.urdf.xacro   | -->
<!-- |    EDITING THIS FILE BY HAND IS NOT RECOMMENDED                                 | -->
<!-- =================================================================================== -->
<robot name="igus_rebel">
  <link name="base_link">
    <inertial>
      <origin rpy="0 0 0" xyz="-0.0011101 -0.00059494 0.040917"/>
      <mass value="4.2944"/>
      <inertia ixx="0.098117" ixy="4.4465E-07" ixz="3.3605E-05" iyy="0.086593" iyz="-1.8837E-06" izz="0.12838"/>
    </inertial>
    <visual>
      <origin rpy="0 0 0" xyz="0 0 0"/>
      <geometry>
        <mesh filename="file:///home/me1baj/igus_ws/install/igus_rebel_description/share/igus_rebel_description/meshes/robolink_rebel2/base_link.stl"/>
      </geometry>
      <material name="">
        <color rgba="0.75294 0.75294 0.75294 1"/>
      </material>
    </visual>
    <collision>
      <origin rpy="0 0 0" xyz="0 0 0"/>
      <geometry>
        <mesh filename="file:///home/me1baj/igus_ws/install/igus_rebel_description/share/igus_rebel_description/meshes/robolink_rebel2/simplified_base_link.stl"/>
      </geometry>
    </collision>
  </link>
  <link name="motor1">
    <inertial>
      <origin rpy="0 0 0" xyz="0.00015243 0.00010812 -0.014668"/>
      <mass value="2"/>
      <inertia ixx="0.024041" ixy="8.3398E-08" ixz="-7.2533E-07" iyy="0.024081" iyz="-6.2967E-07" izz="0.037427"/>
    </inertial>
    <visual>
      <origin rpy="0 0 0" xyz="0 0 0"/>
      <geometry>
        <mesh filename="file:///home/me1baj/igus_ws/install/igus_rebel_description/share/igus_rebel_description/meshes/robolink_rebel2/motor1.stl"/>
      </geometry>
      <material name="">
        <color rgba="0.75294 0.75294 0.75294 1"/>
      </material>
    </visual>
    <collision>
      <origin rpy="0 0 0" xyz="0 0 0"/>
      <geometry>
        <mesh filename="file:///home/me1baj/igus_ws/install/igus_rebel_description/share/igus_rebel_description/meshes/robolink_rebel2/simplified_motor1.stl"/>
      </geometry>
    </collision>
  </link>
  <joint name="J_motor1" type="fixed">
    <origin rpy="0 0 3.1416" xyz="0 0 0.1462"/>
    <parent link="base_link"/>
    <child link="motor1"/>
    <axis xyz="0 0 0"/>
  </joint>
  <link name="link1">
    <inertial>
      <origin rpy="0 0 0" xyz="2.5064E-06 -0.031151 0.06301"/>
      <mass value="1.9246"/>
      <inertia ixx="0.046865" ixy="-3.7969E-09" ixz="5.1665E-09" iyy="0.04904" iyz="0.00010721" izz="0.030611"/>
    </inertial>
    <visual>
      <origin rpy="0 0 0" xyz="0 0 0"/>
      <geometry>
        <mesh filename="file:///home/me1baj/igus_ws/install/igus_rebel_description/share/igus_rebel_description/meshes/robolink_rebel2/link1.stl"/>
      </geometry>
      <material name="">
        <color rgba="0.79216 0.81961 0.93333 1"/>
      </material>
    </visual>
    <collision>
      <origin rpy="0 0 0" xyz="0 0 0"/>
      <geometry>
        <mesh filename="file:///home/me1baj/igus_ws/install/igus_rebel_description/share/igus_rebel_description/meshes/robolink_rebel2/simplified_link1.stl"/>
      </geometry>
    </collision>
  </link>
  <joint name="joint1" type="revolute">
    <origin rpy="0 0 0" xyz="0 0 0"/>
    <parent link="motor1"/>
    <child link="link1"/>
    <axis xyz="0 0 -1"/>
    <limit effort="330" lower="-3.1241" upper="3.1241" velocity="2.16"/>
    <dynamics damping="0.0" friction="0.0"/>
  </joint>
  <link name="motor2">
    <inertial>
      <origin rpy="0 0 0" xyz="0.00015243 0.014668 0.00010812"/>
      <mass value="2"/>
      <inertia ixx="0.024041" ixy="7.2533E-07" ixz="8.3398E-08" iyy="0.037427" iyz="6.2967E-07" izz="0.024081"/>
    </inertial>
    <visual>
      <origin rpy="0 0 0" xyz="0 0 0"/>
      <geometry>
        <mesh filename="file:///home/me1baj/igus_ws/install/igus_rebel_description/share/igus_rebel_description/meshes/robolink_rebel2/motor2.stl"/>
      </geometry>
      <material name="">
        <color rgba="0.75294 0.75294 0.75294 1"/>
      </material>
    </visual>
    <collision>
      <origin rpy="0 0 0" xyz="0 0 0"/>
      <geometry>
        <mesh filename="file:///home/me1baj/igus_ws/install/igus_rebel_description/share/igus_rebel_description/meshes/robolink_rebel2/simplified_motor2.stl"/>
      </geometry>
    </collision>
  </link>
  <joint name="J_motor2" type="fixed">
    <origin rpy="0 0 0" xyz="0 -0.0225000000000001 0.106"/>
    <parent link="link1"/>
    <child link="motor2"/>
    <axis xyz="0 0 0"/>
  </joint>
  <link name="link2">
    <inertial>
      <origin rpy="0 0 0" xyz="0.023424 0.025337 0.10782"/>
      <mass value="5.689"/>
      <inertia ixx="0.1162" ixy="-2.0164E-11" ixz="-0.00018569" iyy="0.10155" iyz="5.9595E-10" izz="0.08965"/>
    </inertial>
    <visual>
      <origin rpy="0 0 0" xyz="0 0 0"/>
      <geometry>
        <mesh filename="file:///home/me1baj/igus_ws/install/igus_rebel_description/share/igus_rebel_description/meshes/robolink_rebel2/link2.stl"/>
      </geometry>
      <material name="">
        <color rgba="0.75294 0.75294 0.75294 1"/>
      </material>
    </visual>
    <collision>
      <origin rpy="0 0 0" xyz="0 0 0"/>
      <geometry>
        <mesh filename="file:///home/me1baj/igus_ws/install/igus_rebel_description/share/igus_rebel_description/meshes/robolink_rebel2/simplified_link2.stl"/>
      </geometry>
    </collision>
  </link>
  <joint name="joint2" type="revolute">
    <origin rpy="0 0 0" xyz="0 0.049 0"/>
    <parent link="motor2"/>
    <child link="link2"/>
    <axis xyz="0 -1 0"/>
    <limit effort="330" lower="-1.4835" upper="2.4435" velocity="2.16"/>
    <dynamics damping="0.0" friction="0.0"/>
  </joint>
  <link name="motor3">
    <inertial>
      <origin rpy="0 0 0" xyz="0.00015243 0.014668 0.00010812"/>
      <mass value="2.0785"/>
      <inertia ixx="0.024041" ixy="7.2533E-07" ixz="8.3398E-08" iyy="0.037427" iyz="6.2967E-07" izz="0.024081"/>
    </inertial>
    <visual>
      <origin rpy="0 0 0" xyz="0 0 0"/>
      <geometry>
        <mesh filename="file:///home/me1baj/igus_ws/install/igus_rebel_description/share/igus_rebel_description/meshes/robolink_rebel2/motor3.stl"/>
      </geometry>
      <material name="">
        <color rgba="0.75294 0.75294 0.75294 1"/>
      </material>
    </visual>
    <collision>
      <origin rpy="0 0 0" xyz="0 0 0"/>
      <geometry>
        <mesh filename="file:///home/me1baj/igus_ws/install/igus_rebel_description/share/igus_rebel_description/meshes/robolink_rebel2/simplified_motor3.stl"/>
      </geometry>
    </collision>
  </link>
  <joint name="J_motor3" type="fixed">
    <origin rpy="0 0 0" xyz="0 -0.049 0.24152"/>
    <parent link="link2"/>
    <child link="motor3"/>
    <axis xyz="0 0 0"/>
  </joint>
  <link name="link3">
    <inertial>
      <origin rpy="0 0 0" xyz="1.8683E-06 0.030601 0.032537"/>
      <mass value="2.5429"/>
      <inertia ixx="0.051458" ixy="3.7774E-09" ixz="-4.5694E-09" iyy="0.057983" iyz="0.00010721" izz="0.035205"/>
    </inertial>
    <visual>
      <origin rpy="0 0 0" xyz="0 0 0"/>
      <geometry>
        <mesh filename="file:///home/me1baj/igus_ws/install/igus_rebel_description/share/igus_rebel_description/meshes/robolink_rebel2/link3.stl"/>
      </geometry>
      <material name="">
        <color rgba="0.75294 0.75294 0.75294 1"/>
      </material>
    </visual>
    <collision>
      <origin rpy="0 0 0" xyz="0 0 0"/>
      <geometry>
        <mesh filename="file:///home/me1baj/igus_ws/install/igus_rebel_description/share/igus_rebel_description/meshes/robolink_rebel2/simplified_link3.stl"/>
      </geometry>
    </collision>
  </link>
  <joint name="joint3" type="revolute">
    <origin rpy="0 0 0" xyz="0 0.0225 0"/>
    <parent link="motor3"/>
    <child link="link3"/>
    <axis xyz="0 -1 0"/>
    <limit effort="330" lower="-1.39626" upper="2.61799" velocity="2.16"/>
    <dynamics damping="0.0" friction="0.0"/>
  </joint>
  <link name="motor4">
    <inertial>
      <origin rpy="0 0 0" xyz="0.00015243 -0.00010812 0.014668"/>
      <mass value="2.0785"/>
      <inertia ixx="0.024041" ixy="-8.3398E-08" ixz="7.2533E-07" iyy="0.024081" iyz="-6.2967E-07" izz="0.037427"/>
    </inertial>
    <visual>
      <origin rpy="0 0 0" xyz="0 0 0"/>
      <geometry>
        <mesh filename="file:///home/me1baj/igus_ws/install/igus_rebel_description/share/igus_rebel_description/meshes/robolink_rebel2/motor4.stl"/>
      </geometry>
      <material name="">
        <color rgba="0.75294 0.75294 0.75294 1"/>
      </material>
    </visual>
    <collision>
      <origin rpy="0 0 0" xyz="0 0 0"/>
      <geometry>
        <mesh filename="file:///home/me1baj/igus_ws/install/igus_rebel_description/share/igus_rebel_description/meshes/robolink_rebel2/simplified_motor4.stl"/>
      </geometry>
    </collision>
  </link>
  <joint name="J_motor4" type="fixed">
    <origin rpy="0 0 0" xyz="0.0013449814287804 0 0.105479407401356"/>
    <parent link="link3"/>
    <child link="motor4"/>
    <axis xyz="0 0 0"/>
  </joint>
  <link name="link4">
    <inertial>
      <origin rpy="0 0 0" xyz="-0.0070458 -0.00089773 0.05185"/>
      <mass value="2.2059"/>
      <inertia ixx="0.02402" ixy="1.096E-07" ixz="2.3983E-05" iyy="0.025662" iyz="-1.1343E-06" izz="0.030673"/>
    </inertial>
    <visual>
      <origin rpy="0 0 0" xyz="0 0 0"/>
      <geometry>
        <mesh filename="file:///home/me1baj/igus_ws/install/igus_rebel_description/share/igus_rebel_description/meshes/robolink_rebel2/link4.stl"/>
      </geometry>
      <material name="">
        <color rgba="0.75294 0.75294 0.75294 1"/>
      </material>
    </visual>
    <collision>
      <origin rpy="0 0 0" xyz="0 0 0"/>
      <geometry>
        <mesh filename="file:///home/me1baj/igus_ws/install/igus_rebel_description/share/igus_rebel_description/meshes/robolink_rebel2/simplified_link4.stl"/>
      </geometry>
    </collision>
  </link>
  <joint name="joint4" type="revolute">
    <origin rpy="0 0 0" xyz="0 0 0.052"/>
    <parent link="motor4"/>
    <child link="link4"/>
    <axis xyz="0 0 1"/>
    <limit effort="330" lower="-3.12414" upper="3.12414" velocity="2.16"/>
    <dynamics damping="0.0" friction="0.0"/>
  </joint>
  <link name="motor5">
    <inertial>
      <origin rpy="0 0 0" xyz="3.9518E-05 0.02054 -0.00015792"/>
      <mass value="1.3011"/>
      <inertia ixx="0.010922" ixy="3.1358E-08" ixz="1.683E-08" iyy="0.014448" iyz="-3.8659E-08" izz="0.010868"/>
    </inertial>
    <visual>
      <origin rpy="0 0 0" xyz="0 0 0"/>
      <geometry>
        <mesh filename="file:///home/me1baj/igus_ws/install/igus_rebel_description/share/igus_rebel_description/meshes/robolink_rebel2/motor5.stl"/>
      </geometry>
      <material name="">
        <color rgba="0.75294 0.75294 0.75294 1"/>
      </material>
    </visual>
    <collision>
      <origin rpy="0 0 0" xyz="0 0 0"/>
      <geometry>
        <mesh filename="file:///home/me1baj/igus_ws/install/igus_rebel_description/share/igus_rebel_description/meshes/robolink_rebel2/simplified_motor5.stl"/>
      </geometry>
    </collision>
  </link>
  <joint name="J_motor5" type="fixed">
    <origin rpy="0 0 0" xyz="0 -0.0182 0.142"/>
    <parent link="link4"/>
    <child link="motor5"/>
    <axis xyz="0 0 0"/>
  </joint>
  <link name="link5">
    <inertial>
      <origin rpy="0 0 0" xyz="7.5874E-05 0.022847 0.026585"/>
      <mass value="0.70922"/>
      <inertia ixx="0.0091752" ixy="-5.1443E-08" ixz="-7.751E-09" iyy="0.0086093" iyz="2.4553E-05" izz="0.0079966"/>
    </inertial>
    <visual>
      <origin rpy="0 0 0" xyz="0 0 0"/>
      <geometry>
        <mesh filename="file:///home/me1baj/igus_ws/install/igus_rebel_description/share/igus_rebel_description/meshes/robolink_rebel2/link5.stl"/>
      </geometry>
      <material name="">
        <color rgba="0.75294 0.75294 0.75294 1"/>
      </material>
    </visual>
    <collision>
      <origin rpy="0 0 0" xyz="0 0 0"/>
      <geometry>
        <mesh filename="file:///home/me1baj/igus_ws/install/igus_rebel_description/share/igus_rebel_description/meshes/robolink_rebel2/simplified_link5.stl"/>
      </geometry>
    </collision>
  </link>
  <joint name="joint5" type="continuous">
    <origin rpy="0 0 0" xyz="0 0.0182 0"/>
    <parent link="motor5"/>
    <child link="link5"/>
    <axis xyz="0 -1 0"/>
    <limit effort="330" lower="-1.65806" upper="1.65806" velocity="2.16"/>
    <dynamics damping="0.0" friction="0.0"/>
  </joint>
  <link name="link6">
    <inertial>
      <origin rpy="0 0 0" xyz="-0.00016088 -4.7449E-05 0.021219"/>
      <mass value="1.2658"/>
      <inertia ixx="0.010763" ixy="-2.2861E-07" ixz="-4.9144E-08" iyy="0.010792" iyz="-2.2502E-08" izz="0.014496"/>
    </inertial>
    <visual>
      <origin rpy="0 0 0" xyz="0 0 0"/>
      <geometry>
        <mesh filename="file:///home/me1baj/igus_ws/install/igus_rebel_description/share/igus_rebel_description/meshes/robolink_rebel2/link6.stl"/>
      </geometry>
      <material name="">
        <color rgba="0.75294 0.75294 0.75294 1"/>
      </material>
    </visual>
    <collision>
      <origin rpy="0 0 0" xyz="0 0 0"/>
      <geometry>
        <mesh filename="file:///home/me1baj/igus_ws/install/igus_rebel_description/share/igus_rebel_description/meshes/robolink_rebel2/simplified_link6.stl"/>
      </geometry>
    </collision>
  </link>
  <joint name="joint6" type="revolute">
    <origin rpy="0 0 0" xyz="0 0 0.0768"/>
    <parent link="link5"/>
    <child link="link6"/>
    <axis xyz="0 0 1"/>
    <limit effort="330" lower="-3.12414" upper="3.12414" velocity="2.16"/>
    <dynamics damping="0.0" friction="0.0"/>
  </joint>
  <ros2_control name="rebel_arm_controller" type="system">
    <hardware>
      <plugin>Igus/Rebel</plugin>
    </hardware>
    <joint name="joint1">
      <command_interface name="velocity"/>
      <state_interface name="position"/>
      <state_interface name="velocity"/>
    </joint>
    <joint name="joint2">
      <command_interface name="velocity"/>
      <state_interface name="position"/>
      <state_interface name="velocity"/>
    </joint>
    <joint name="joint3">
      <command_interface name="velocity"/>
      <state_interface name="position"/>
      <state_interface name="velocity"/>
    </joint>
    <joint name="joint4">
      <command_interface name="velocity"/>
      <state_interface name="position"/>
      <state_interface name="velocity"/>
    </joint>
    <joint name="joint5">
      <command_interface name="velocity"/>
      <state_interface name="position"/>
      <state_interface name="velocity"/>
    </joint>
    <joint name="joint6">
      <command_interface name="velocity"/>
      <state_interface name="position"/>
      <state_interface name="velocity"/>
    </joint>
  </ros2_control>
  <link name="world"/>
  <joint name="world_joint" type="fixed">
    <parent link="world"/>
    <child link="base_link"/>
    <origin rpy="0.0 0.0 0.0" xyz="0.0 0.0 0.0"/>
  </joint>
</robot>
